Workbook
Name ARCHITECT: '[1]Load Sheet'!$D$11
Name ARPEF: '[2]CAT - CODE'!$G$1524
Name BF: '[2]CAT - CODE'!$G$1528
Name BIDDATE: '[1]Load Sheet'!$D$10
Name BLDAREA: '[1]Load Sheet'!$D$12
Name BUDGET_DATA: '[3]Budget Tracker'!$AK$6:$CX$116
Name BUDGET_STATUS: '[3]Budget Tracker'!$AK$5:$CX$5
Name BUDGET_TITLE_FY: '[3]Budget Tracker'!$AK$4:$CX$4
Name BUDGET_TITLE_MONTH: '[3]Budget Tracker'!$AK$2:$CX$2
Name BUDGET_TITLE_QUARTER: '[3]Budget Tracker'!$AK$3:$CX$3
Name CB_Precast: '[4]Option 1.2A'!$J$19:$L$21
Name CB_Procurement: '[4]Option 1.2A'!$N$50:$N$69
Name cb_sChart10D6460A_opts: "1, 1, 1, False, 2, True, False, , 0, False, False, 1, 1"
Name cb_sChart10D65256_opts: "1, 1, 1, False, 2, True, False, , 0, False, False, 1, 1"
Name cb_sChart10D653EB_opts: "1, 1, 1, False, 2, True, False, , 0, False, False, 1, 1"
Name cb_sChart10D65893_opts: "1, 1, 1, False, 2, True, False, , 0, False, False, 1, 1"
Name cb_sChart12595BBC_opts: "1, 1, 1, False, 2, True, False, , 0, False, False, 2, 2"
Name cb_sChart12595E44_opts: "1, 3, 1, False, 2, True, False, , 0, True, False, 2, 2"
Name cb_sChartEE4CE1B_opts: "1, 4, 1, False, 2, False, False, , 0, False, False, 1, 1"
Name cb_sChartEE4CF99_opts: "1, 1, 1, False, 2, False, False, , 0, False, False, 1, 1"
Name cb_sChartEE4DD06_opts: "1, 1, 1, False, 2, False, False, , 0, False, False, 1, 2"
Name cb_sChartEE4E93B_opts: "1, 1, 1, False, 2, False, False, , 0, False, False, 1, 1"
Name cb_sChartEE51E95_opts: "1, 1, 1, False, 2, False, False, , 0, False, False, 1, 1"
Name cb_sChartEED7645_opts: "1, 1, 1, False, 2, False, False, , 0, False, False, 1, 1"
Name cb_sChartEEDA195_opts: "1, 1, 1, False, 2, False, False, , 0, False, False, 1, 1"
Name cb_sChartEEDC338_opts: "1, 1, 1, False, 2, False, False, , 0, False, False, 1, 1"
Name cb_sChartEEDEDB8_opts: "1, 1, 1, False, 2, False, False, , 0, False, True, 1, 1"
Name cb_sChartEEDEE5A_opts: "1, 3, 1, False, 2, True, False, , 0, False, True, 1, 1"
Name cb_sChartEEDF178_opts: "1, 3, 1, False, 2, False, False, , 0, False, True, 1, 1"
Name cb_sChartF6A6B11_opts: "1, 1, 1, False, 2, True, False, , 0, False, False, 1, 1"
Name cb_sChartFD191DC_opts: "1, 3, 1, False, 2, True, False, , 0, False, True, 1, 1"
Name cb_sChartFD1A245_opts: "1, 3, 1, False, 2, True, False, , 0, False, True, 1, 1"
Name cb_sChartFD3F0E9_opts: "1, 3, 1, False, 2, True, False, , 0, False, False, 1, 1"
Name cb_sChartFD3F27E_opts: "1, 3, 1, False, 2, True, False, , 0, False, True, 1, 1"
Name cb_sChartFD58483_opts: "1, 1, 1, False, 2, True, False, , 0, False, False, 1, 1"
Name cb_sChartFD5C4CD_opts: "1, 1, 1, False, 2, True, False, , 0, False, False, 1, 1"
Name cb_sChartFD5D4CE_opts: "1, 1, 1, False, 2, True, False, , 0, False, False, 1, 1"
Name cb_sChartFD5DF34_opts: "1, 1, 1, False, 2, True, False, , 0, False, False, 1, 1"
Name cb_sChartFD5EFC0_opts: "1, 1, 1, False, 2, True, False, , 0, False, False, 1, 1"
Name cb_sChartFD5FDB9_opts: "1, 1, 1, False, 2, True, False, , 0, False, False, 1, 1"
Name cb_sChartFE54712_opts: "1, 3, 1, False, 2, True, False, , 0, False, True, 1, 1"
Name CB_Screw: '[4]Option 1.2A'!$M$19:$P$21
Name CIPEF: '[2]CAT - CODE'!$G$1517
Name CLEARHEIGHT: '[1]Load Sheet'!$D$13
Name CODE_PREFIX_L3_E: '[3]Package Register'!$AO$217:$AO$325+'[3]Package Register'!$AO$217:$AO$360
Name COMPANY_NO: OFFSET('[5]Proj Input'!$B$4,0,0,COUNTA('[5]Proj Input'!$B$4:$B$13),1)
Name COPEF: '[2]CAT - CODE'!$G$1516
Name CorrespondingList: OFFSET(INDIRECT(ADDRESS(MATCH(Val1Cell,Objects,0)+112,2,,,"PCO")),0,0,COUNTIF(Objects,Val1Cell),1)
Name CorrespondingList: OFFSET(INDIRECT(ADDRESS(MATCH(Val1Cell,Objects,0)+112,2,,,"PCO")),0,0,COUNTIF(Objects,Val1Cell),1)
Name CorrespondingList: OFFSET(INDIRECT(ADDRESS(MATCH(Val1Cell,Objects,0)+112,2,,,"PCO")),0,0,COUNTIF(Objects,Val1Cell),1)
Name CorrespondingList2: OFFSET(INDIRECT(ADDRESS(MATCH(Val1Cell,Objects,0)+112,2,,,"PCO")),0,0,COUNTIF(Objects,Val1Cell),1)
Name CorrespondingList2: OFFSET(INDIRECT(ADDRESS(MATCH(Val1Cell,Objects,0)+112,2,,,"PCO")),0,0,COUNTIF(Objects,Val1Cell),1)
Name CorrespondingList2: OFFSET(INDIRECT(ADDRESS(MATCH(Val1Cell,Objects,0)+112,2,,,"PCO")),0,0,COUNTIF(Objects,Val1Cell),1)
Name CREW_TABLE: [6]INFO!$B$13:$G$60
Name CURRENCY: [6]INFO!$C$4:$E$10
Name CURRENCY2: [6]INFO!$C$4:$E$10
Name DCLABSTOT: 24738790
Name DCLABTOT: 27763421
Name DCMATLCTOT: 1233848
Name DCMATLTOT: 11167072

Sheet Preface
B12: Doc Ref | C12: 855DC-1540-MX-IT-0006
B14: Title | C14: Decarb Green Systems (DGS) Delphi Interface Requirements Verification and Acceptance Matrix (RVAM)
B15: Author | C15: Neil Hall | E15: Position | F15: Systems Engineer | H15: Department | I15: Decarb Systems Delivery
B16: Reviewers | C16: Abby Buters | E16: Position | F16: Green Systems Development Manager | H16: Department | I16: Green Systems Program
C17: Mark Mennell | E17: Position | F17: Principal Software Engineer | H17: Department | I17: Green Systems Program
C18: Andrew Malcolm | E18: Position | F18: Head of Green Systems | H18: Department | I18: Green Systems Program
B21: Purpose
B22: This interface requirements verification and acceptance matrix (RVAM) is developed to provide the Decarb Green Systems programme with a structured, traceable method for capturing, reviewing, and refining interface requirements before they are entered into the requirements repository. This tool is intended to support requirements gathering and engineering during the early stages of system definition and requirements specification. It allows engineers, managers, and stakeholders to record draft requirements derived from the system architecture and interface register and to conduct initial reviews for clarity, completeness, and consistency.
B24: About Requirements Engineering
B25: Requirements engineering is a structured approach focused on defining, analysing, documenting, verifying and validating the needs and constraints that stakeholders require a system to meet. It ensures that all functions, interfaces, and performance expectations are understood and agreed upon before design and implementation begin. Practical requirements engineering reduces project risks, supports traceability throughout the system lifecycle, and enhances verification and validation outcomes.
B27: Intended Use
B28: The RVAM should be used collaboratively by program and project teams and subject matter experts to: - Capture candidate requirements in a consistent, reviewable format. - Record comments, review status, and actions from requirements review sessions. - Identify dependencies and interfaces between requirements. - Prepare clean, validated inputs for capture into the requirements repository. - Provide a mature and traceable set of baseline interface requirements aligned to systems engineering best practice (ISO/IEC 15288).
B30: Scope
B31: This RVAM is intended solely for the initial capture and review of interface requirements before they are imported into the requirements repository. The scope of this template is limited to identifying, reviewing, and documenting requirements in all lifecycle phases. It should be used to capture verification results, validation methods, evidence, and change management records throughout the lifecycle of the requirements.
B33: Table Field Definitions
B34: Field | D34: Definition / Purpose
B35: Req ID | D35: A unique identifier assigned to each requirement for traceability and reference. This ID remains consistent through the RMS import and lifecycle.
B36: Requirement Text | D36: The full, precise statement of the requirement, written in clear and testable language that defines what the system or subsystem must achieve.
B37: Artifact Type | D37: The classification of the requirement according to its nature, such as System, Subsystem, Functional, Interface, etc.
B38: Source | D38: The origin of the requirement, such as a stakeholder document, standard, contract clause, system specification, or engineering analysis.
B39: Rationale | D39: The reason the requirement exists, describing the intent or justification (e.g. regulatory compliance, operational need, safety objective).
B40: Criticality Level | D40: An assessment of the requirement’s importance or impact on the system performance, safety, or compliance (e.g. High, Medium, Low, Very Low).
B41: Quality Flaw | D41: Notes identifying any issues or ambiguities in the requirement text, such as incomplete, unverifiable, or unclear wording, to guide re-drafting.
B42: Review Notes | D42: Comments and observations made during the review process, including recommended actions, clarifications, or cross-references.
B43: Discipline | D43: The engineering or functional area responsible for or affected by the requirement.
B44: WBS L1 / L2 / L3 | D44: References to the corresponding levels of the Work Breakdown Structure (WBS) to align each requirement with its relevant project scope element. These support hierarchical traceability from program level to subsystem.
B45: Facility Code | D45: WBS numeric identifier for to support hierarchical traceability from program level to subsystem.
... B49: Verification Method | D49: The intended means by which the requirement will be verified once implemented. Typical categories include Analysis, Inspection, Test, or Demonstration.
B51: Requirement Type Definitions
B52: Requirement Type | D52: Definition
B53: Business Requirement | D53: A high-level need or objective that reflects what the organisation is trying to achieve. It expresses business outcomes, value drivers, or strategic goals rather than technical solutions.
B54: Functional Requirement | D54: A description of what a system, component, or process must do. It defines behaviours, actions, inputs, outputs, and rules required to achieve a capability.
B55: System Requirement | D55: A requirement allocated to the system as a whole, defining the performance, behaviour, constraints, or characteristics the system must meet. System requirements sit above subsystem-level detail.
B56: Project/Subsystem Requirement | D56: A requirement specific to an individual subsystem or project component. It refines system-level requirements into implementable expectations for a defined part of the solution.
B57: Interface Requirement | D57: A requirement describing how two systems, subsystems, components, or organisations interact. It specifies data, commands, physical connections, timing, protocols, and responsibilities at system boundaries.
B58: Scope Requirement | D58: A requirement that defines what is included or excluded from the project, system, or design boundary. It clarifies limits, assumptions, and expectations to control scope and prevent ambiguity.
B59: Technical Requirement | D59: A requirement specifying a technical constraint or characteristic, such as performance metrics, capacity, standards compliance, environmental conditions, safety margins, or engineering rules.
B60: Process Requirement | D60: A requirement describing how an activity must be conducted. It defines procedural steps, workflows, responsibilities, or governance needed to deliver or operate the system.
B61: Information | D61: Content provided for context, explanation, or clarification that does not represent a requirement and does not impose obligations on the solution.
B62: Heading | D62: A structural label used to group or organise requirements. It is not itself a requirement.
...

Sheet Document Control 
B13: Revision | C13: Date | E13: Author | G13: Revision Desciption
B14: A | C14: 46007 | E14: Neil Hall | G14: First draft of Delphi interface requirements for review. Requirement are derived from the Decarb Green Systems Architecture. Link to the system architecture: https://fortescue-dgs.netlify.app
B15: B | C15: 16/01/2026 | E15: Neil Hall, Sam Gould | G15: Revised the document preface. Updated to fix inaccuracies in the interface description and to include stakeholder review feedback.

Sheet Requirements
A1: Req ID | B1: Lvl | C1: Requirement Text | D1: Artifact Type | E1: Source | F1: Apportionment | G1: Rationale | H1: Supporting Information from Interface Register | I1: Criticality Level | J1: Quality Flaw | K1: Verification Method | L1: Validation Method | M1: Requirement Status
A2: GSP-RH-0001 | B2: 1 | C2: Green Systems Interface Requirements | D2: Heading | M2: N/A
A3: GSP-RH-0002 | B3: 2 | C3: Delphi Interface Requirements | D3: Heading | M3: N/A
A4: GSP-IR-0003 | C4: The interface shall provide Heavy Mining Equipment (HME) operational and load-profile input data to Delphi at a frequency of 1 Hz (one update per second), with a maximum end-to-end latency of up to 2 seconds, to support fleet simulation and energy feasibility analysis. | D4: Interface Requirement | E4: Green Systems Interface Register, Interface DGS-I_0023 | F4: Delphi | G4: Feasibility analysis requires timely data; delayed or missing data prevents simulation and energy checks. | H4: 859DC-1410-001 HaulX|855DC-1541-DEL Delphi_x000D_ Project - Project Interface_x000D_ Technical-Data/Software_x000D_ This interface provides a near-term forecast of fleet energy consumption. This depends on the HaulX forecast horizon, based on a dispatch plan and mine plan. 30-40% of load based on mobile asset energy consumption. Frequency, resolution and horizon need to be determined for truck and excavator fleet on charge. State of charge, estimated time of completion._x000D_ The criticality level is LOW because, although Delphi receives fleet energy forecasts from HaulX to support planning and optimisation, the interface does not affect real-time haulage operations, safety, or production continuity. If the interface fails, Haulage and mine operations continue normally, though forecast accuracy and decision-making may be reduced. | M4: Draft
A5: GSP-IR-0004 | C5: The interface shall ensure completeness of all mandatory Heavy Mining Equipment (HME) load-profile data fields used by the Eclipse simulation engine. | D5: Interface Requirement | E5: Green Systems Interface Register, Interface DGS-I_0023 | F5: Delphi | G5: Missing fields lead to invalid or failed simulations. | H5: 859DC-1410-001 HaulX|855DC-1541-DEL Delphi_x000D_ Project - Project Interface_x000D_ Technical-Data/Software_x000D_ This interface provides a near-term forecast of fleet energy consumption. This depends on the HaulX forecast horizon, based on a dispatch plan and mine plan. 30-40% of load based on mobile asset energy consumption. Frequency, resolution and horizon need to be determined for truck and excavator fleet on charge. State of charge, estimated time of completion._x000D_ The criticality level is LOW because, although Delphi receives fleet energy forecasts from HaulX to support planning and optimisation, the interface does not affect real-time haulage operations, safety, or production continuity. If the interface fails, Haulage and mine operations continue normally, though forecast accuracy and decision-making may be reduced. | M5: Draft
A6: GSP-IR-0005 | C6: The interface shall ensure integrity of transmitted values, including protection against corruption and preservation of source identifiers and timestamps. | D6: Interface Requirement | E6: Green Systems Interface Register, Interface DGS-I_0023 | F6: Delphi | G6: Compromised integrity produces incorrect feasibility results and curtailment decisions. | H6: 859DC-1410-001 HaulX|855DC-1541-DEL Delphi_x000D_ Project - Project Interface_x000D_ Technical-Data/Software_x000D_ This interface provides a near-term forecast of fleet energy consumption. This depends on the HaulX forecast horizon, based on a dispatch plan and mine plan. 30-40% of load based on mobile asset energy consumption. Frequency, resolution and horizon need to be determined for truck and excavator fleet on charge. State of charge, estimated time of completion._x000D_ The criticality level is LOW because, although Delphi receives fleet energy forecasts from HaulX to support planning and optimisation, the interface does not affect real-time haulage operations, safety, or production continuity. If the interface fails, Haulage and mine operations continue normally, though forecast accuracy and decision-making may be reduced. | M6: Draft
A7: GSP-IR-0006 | C7: The interface shall provide deterministic error handling and clear notifications when Heavy Mining Equipment (HME) data is missing, delayed, or invalid. | D7: Interface Requirement | E7: Green Systems Interface Register, Interface DGS-I_0023 | F7: Delphi | G7: Clear fault visibility is required to avoid silent degradation of planning capability. | H7: 859DC-1410-001 HaulX|855DC-1541-DEL Delphi_x000D_ Project - Project Interface_x000D_ Technical-Data/Software_x000D_ This interface provides a near-term forecast of fleet energy consumption. This depends on the HaulX forecast horizon, based on a dispatch plan and mine plan. 30-40% of load based on mobile asset energy consumption. Frequency, resolution and horizon need to be determined for truck and excavator fleet on charge. State of charge, estimated time of completion._x000D_ The criticality level is LOW because, although Delphi receives fleet energy forecasts from HaulX to support planning and optimisation, the interface does not affect real-time haulage operations, safety, or production continuity. If the interface fails, Haulage and mine operations continue normally, though forecast accuracy and decision-making may be reduced. | M7: Draft
A8: GSP-IR-0007 | C8: The interface shall provide Delphi with continuous access to Snowflake datasets containing historical and actual operational data required for short-term planning. | D8: Interface Requirement | E8: Green Systems Interface Register, Interface DGS-I_0345 | F8: Delphi | G8: Continuous access to historical and actual data is required to support accurate short-term planning; interruptions or gaps degrade forecast quality and decision-making. | H8: 005OP-0000-006 Snowflake (General)|855DC-1541-DEL Delphi_x000D_ Project - Project Interface_x000D_ Technical-Data/Software_x000D_ This interface collects general actuals and historical data residing in Snowflake. Snowflake provides a 'time travel' function, which is from 1 day (default) up to a maximum of 90 days._x000D_ This interface is rated HIGH because accurate historical and actual data underpins short-term forecasting, model validation, and operational planning accuracy. Loss or corruption of this data materially degrades forecast reliability, increasing the risk of incorrect generation dispatch, inefficient curtailment decisions, and potential instability in power management. Reliable historical data is essential for maintaining confidence in optimisation and planning outputs. | M8: Draft
A9: GSP-IR-0008 | C9: The interface shall maintain a minimum availability of 99.9% each calendar month, allowing no more than 43.2 minutes of unplanned downtime per month, to ensure planning and forecasting accuracy is not materially degraded | D9: Interface Requirement | E9: Green Systems Interface Register, Interface DGS-I_0345 | F9: Delphi | G9: Unplanned outages increase the risk of unplanned load curtailment and unsafe conditions. | H9: 005OP-0000-006 Snowflake (General)|855DC-1541-DEL Delphi_x000D_ Project - Project Interface_x000D_ Technical-Data/Software_x000D_ This interface collects general actuals and historical data residing in Snowflake. Snowflake provides a 'time travel' function, which is from 1 day (default) up to a maximum of 90 days._x000D_ This interface is rated HIGH because accurate historical and actual data underpins short-term forecasting, model validation, and operational planning accuracy. Loss or corruption of this data materially degrades forecast reliability, increasing the risk of incorrect generation dispatch, inefficient curtailment decisions, and potential instability in power management. Reliable historical data is essential for maintaining confidence in optimisation and planning outputs. | M9: Draft
A10: GSP-IR-0009 | C10: The interface shall provide version-controlled historical datasets to support consistent retrospective analysis and model training. | D10: Interface Requirement | E10: Green Systems Interface Register, Interface DGS-I_0345 | F10: Delphi | G10: Consistent datasets are needed to reproduce and improve forecasting models. | H10: 005OP-0000-006 Snowflake (General)|855DC-1541-DEL Delphi_x000D_ Project - Project Interface_x000D_ Technical-Data/Software_x000D_ This interface collects general actuals and historical data residing in Snowflake. Snowflake provides a 'time travel' function, which is from 1 day (default) up to a maximum of 90 days._x000D_ This interface is rated HIGH because accurate historical and actual data underpins short-term forecasting, model validation, and operational planning accuracy. Loss or corruption of this data materially degrades forecast reliability, increasing the risk of incorrect generation dispatch, inefficient curtailment decisions, and potential instability in power management. Reliable historical data is essential for maintaining confidence in optimisation and planning outputs. | M10: Draft
A11: GSP-IR-0010 | C11: The interface shall apply data-quality checks, including type, range, and completeness validation, before data is ingested into Delphi. | D11: Interface Requirement | E11: Green Systems Interface Register, Interface DGS-I_0345 | F11: Delphi | G11: Low-quality data can drive unsafe or inefficient planning outcomes. | H11: 005OP-0000-006 Snowflake (General)|855DC-1541-DEL Delphi_x000D_ Project - Project Interface_x000D_ Technical-Data/Software_x000D_ This interface collects general actuals and historical data residing in Snowflake. Snowflake provides a 'time travel' function, which is from 1 day (default) up to a maximum of 90 days._x000D_ This interface is rated HIGH because accurate historical and actual data underpins short-term forecasting, model validation, and operational planning accuracy. Loss or corruption of this data materially degrades forecast reliability, increasing the risk of incorrect generation dispatch, inefficient curtailment decisions, and potential instability in power management. Reliable historical data is essential for maintaining confidence in optimisation and planning outputs. | M11: Draft
A12: GSP-IR-0011 | C12: The interface shall supply real-time operational electrical load data from Ignition SCADA to Delphi for plan-versus-actual calculations. | D12: Interface Requirement | E12: Green Systems Interface Register, Interface DGS-I_0344 | F12: Delphi | G12: Plan-versus-actual comparison requires current load measurements. | H12: 005OP-0000-017 Ignition|855DC-1541-DEL Delphi_x000D_ Project - Project Interface_x000D_ Technical-Data/Software_x000D_ This interface supplies operational data for ground-truth load for plan/forecast vs. actual load calculations._x000D_ This interface is rated HIGH because it provides the authoritative operational load data required to maintain an accurate view of total system demand. Loss, delay, or corruption of this data undermines the integrity of load calculations and forecasting models, increasing the risk of overload conditions, incorrect dispatch or curtailment decisions, and potential safety incidents. Reliable ground-truth data is essential for maintaining power system stability and operational assurance. | M12: Draft
A13: GSP-IR-0012 | C13: The interface shall ensure that SCADA load-data latency does not exceed 2 seconds end-to-end, measured from data capture to availability in the consuming system, to meet the operational threshold required for safe real-time decision-making. | D13: Interface Requirement | E13: Green Systems Interface Register, Interface DGS-I_0344 | F13: Delphi | G13: Excessive latency undermines safe curtailment and control decisions. | H13: 005OP-0000-017 Ignition|855DC-1541-DEL Delphi_x000D_ Project - Project Interface_x000D_ Technical-Data/Software_x000D_ This interface supplies operational data for ground-truth load for plan/forecast vs. actual load calculations._x000D_ This interface is rated HIGH because it provides the authoritative operational load data required to maintain an accurate view of total system demand. Loss, delay, or corruption of this data undermines the integrity of load calculations and forecasting models, increasing the risk of overload conditions, incorrect dispatch or curtailment decisions, and potential safety incidents. Reliable ground-truth data is essential for maintaining power system stability and operational assurance. | M13: Draft
A14: GSP-IR-0013 | C14: The interface shall detect and flag anomalous SCADA load data patterns, including flatlines, spikes, and gaps. | D14: Interface Requirement | E14: Green Systems Interface Register, Interface DGS-I_0344 | F14: Delphi | G14: Anomaly detection reduces the risk of acting on erroneous load information. | H14: 005OP-0000-017 Ignition|855DC-1541-DEL Delphi_x000D_ Project - Project Interface_x000D_ Technical-Data/Software_x000D_ This interface supplies operational data for ground-truth load for plan/forecast vs. actual load calculations._x000D_ This interface is rated HIGH because it provides the authoritative operational load data required to maintain an accurate view of total system demand. Loss, delay, or corruption of this data undermines the integrity of load calculations and forecasting models, increasing the risk of overload conditions, incorrect dispatch or curtailment decisions, and potential safety incidents. Reliable ground-truth data is essential for maintaining power system stability and operational assurance. | M14: Draft
A15: GSP-IR-0014 | C15: The interface shall include metadata, such as timestamps and source identifiers, to support audit and post-event analysis of load data. | D15: Interface Requirement | E15: Green Systems Interface Register, Interface DGS-I_0344 | F15: Delphi | G15: Traceability is required for incident investigation and assurance. | H15: 005OP-0000-017 Ignition|855DC-1541-DEL Delphi_x000D_ Project - Project Interface_x000D_ Technical-Data/Software_x000D_ This interface supplies operational data for ground-truth load for plan/forecast vs. actual load calculations._x000D_ This interface is rated HIGH because it provides the authoritative operational load data required to maintain an accurate view of total system demand. Loss, delay, or corruption of this data undermines the integrity of load calculations and forecasting models, increasing the risk of overload conditions, incorrect dispatch or curtailment decisions, and potential safety incidents. Reliable ground-truth data is essential for maintaining power system stability and operational assurance. | M15: Draft
... A66: GSP-IR-0065 | C66: The interface shall route only aggregated and operationally relevant weather information to the HIVE display, avoiding unnecessary technical detail. | D66: Interface Requirement | E66: Green Systems Interface Register, Interface DGS-I_0213 | F66: Delphi | G66: Operators require concise, actionable information rather than raw data. | H66: Energy Operations (HIVE)|855DC-1541-DEL Delphi_x000D_ Stakeholder - Project Interface_x000D_ Technical-Data/Software_x000D_ Delphi - Aggregated Weather Platform for Actuals & Forecasts (HIVE Display)_x000D_ The purpose of this interface is for Delphi to serve as the central aggregated weather platform, combining actual measured weather data and multiple forecast sources into a single operational view. Energy Operations uses Delphi to monitor real-time and near-term weather conditions - such as wind, irradiance, rainfall, and lightning - via a dedicated display screen in the HIVE control room._x000D_ Intermediate Elements: the Delphi weather aggregation platform, Snowflake datasets, and the HIVE visualisation screen._x000D_ The criticality level is HIGH because reliable, consolidated weather visibility is essential for operational decision-making, forecasting accuracy, and reacting to rapidly changing conditions that affect generation, safety, and dispatch. Failure of this interface causes immediate blindness to changing conditions (e.g., wind gusts or solar drops), risking system instability, inaccurate generation curtailment, or compromising safety protocols (e.g., lightning warnings). | M66: Draft

Sheet Common Data
A2: Artifact Type | B2: Requirement Status | C2: Quality Flaw | D2: Criticality Level | E2: Verification method | F2: Verification Evidence Intent | G2: Verification Evidence Link | H2: Verification Evidence | I2: Verification Justification | J2: Verification Status
A3: Business Requirement | B3: Draft | C3: Untraceable | D3: High | E3: Review | J3: Satisfied
A4: Functional Requirement | B4: Ready for Review | C4: Non‐atomic | D4: Medium | E4: Calculation | J4: Not‐satisfied
A5: System Requirement | B5: Accepted | C5: Ambiguous | D5: Low | E5: Simulation | J5: Partially‐satisfied
A6: Project/Subsystem Requirement | B6: Accepted with Clarification | C6: Duplicate | D6: Very Low | E6: Demonstration
A7: Interface Requirement | B7: Not Accepted | C7: Unverifiable | D7: Unable to Assess | E7: Inspection
A8: Scope Requirement | B8: N/A | C8: Inconsistent | E8: Measurement
A9: Technical Requirement | C9: Unnecessary | E9: Monitoring
A10: Process Requirement | C10: Unattainable | E10: Test
A11: Information | C11: Incomplete | E11: Study
A12: Heading | C12: Multiple Flaws | E12: Analysis
A13: Other | E13: Other

Sheet Requirements Formulas
A1: Req ID | B1: Lvl | C1: Requirement Text | D1: Artifact Type | E1: Source | F1: Apportionment | G1: Rationale | H1: Supporting Information from Interface Register | I1: Criticality Level | J1: Quality Flaw | K1: Verification Method | L1: Validation Method | M1: Requirement Status
A2: {=_xlfn.LET( _xlpm.data,'EA-Fortescue_ReqsImport'!A2:A1000, _xlpm.filtered,_xlfn._xlws.FILTER(_xlpm.data,_xlpm.data<>""), _xlpm.first11,LEFT(_xlpm.filtered,11), _xlpm.last4,VALUE(RIGHT(_xlpm.first11,4)), _xlfn.SORTBY(_xlpm.first11,_xlpm.last4,1) )} -> GSP-RH-0001 | B2: 1 | C2: {=IF(_xlfn.XLOOKUP($A2,LEFT('EA-Fortescue_ReqsImport'!$A:$A,11),'EA-Fortescue_ReqsImport'!R:R)<1,"",_xlfn.XLOOKUP($A2,LEFT('EA-Fortescue_ReqsImport'!$A:$A,11),'EA-Fortescue_ReqsImport'!R:R))} -> Green Systems Interface Requirements | D2: {=IF(_xlfn.XLOOKUP($A2,LEFT('EA-Fortescue_ReqsImport'!$A:$A,11),'EA-Fortescue_ReqsImport'!S:S)<1,"",_xlfn.XLOOKUP($A2,LEFT('EA-Fortescue_ReqsImport'!$A:$A,11),'EA-Fortescue_ReqsImport'!S:S))} -> Heading | E2: {=IF(_xlfn.XLOOKUP($A2,LEFT('EA-Fortescue_ReqsImport'!$A:$A,11),'EA-Fortescue_ReqsImport'!T:T)<1,"",_xlfn.XLOOKUP($A2,LEFT('EA-Fortescue_ReqsImport'!$A:$A,11),'EA-Fortescue_ReqsImport'!T:T))} | F2: {=IF(_xlfn.XLOOKUP($A2,LEFT('EA-Fortescue_ReqsImport'!$A:$A,11),'EA-Fortescue_ReqsImport'!U:U)<1,"",_xlfn.XLOOKUP($A2,LEFT('EA-Fortescue_ReqsImport'!$A:$A,11),'EA-Fortescue_ReqsImport'!U:U))} | G2: {=IF(_xlfn.XLOOKUP($A2,LEFT('EA-Fortescue_ReqsImport'!$A:$A,11),'EA-Fortescue_ReqsImport'!V:V)<1,"",_xlfn.XLOOKUP($A2,LEFT('EA-Fortescue_ReqsImport'!$A:$A,11),'EA-Fortescue_ReqsImport'!V:V))} | H2: {=IF(_xlfn.XLOOKUP($A2,LEFT('EA-Fortescue_ReqsImport'!$A:$A,11),'EA-Fortescue_ReqsImport'!W:W)<1,"",_xlfn.XLOOKUP($A2,LEFT('EA-Fortescue_ReqsImport'!$A:$A,11),'EA-Fortescue_ReqsImport'!W:W))} | M2: {=IF(_xlfn.XLOOKUP($A2,LEFT('EA-Fortescue_ReqsImport'!$A:$A,11),'EA-Fortescue_ReqsImport'!X:X)<1,"N/A",_xlfn.XLOOKUP($A2,LEFT('EA-Fortescue_ReqsImport'!$A:$A,11),'EA-Fortescue_ReqsImport'!X:X))} -> N/A
A3: GSP-RH-0002 | B3: 2 | C3: {=IF(_xlfn.XLOOKUP($A3,LEFT('EA-Fortescue_ReqsImport'!$A:$A,11),'EA-Fortescue_ReqsImport'!R:R)<1,"",_xlfn.XLOOKUP($A3,LEFT('EA-Fortescue_ReqsImport'!$A:$A,11),'EA-Fortescue_ReqsImport'!R:R))} -> Delphi Interface Requirements | D3: {=IF(_xlfn.XLOOKUP($A3,LEFT('EA-Fortescue_ReqsImport'!$A:$A,11),'EA-Fortescue_ReqsImport'!S:S)<1,"",_xlfn.XLOOKUP($A3,LEFT('EA-Fortescue_ReqsImport'!$A:$A,11),'EA-Fortescue_ReqsImport'!S:S))} -> Heading | E3: {=IF(_xlfn.XLOOKUP($A3,LEFT('EA-Fortescue_ReqsImport'!$A:$A,11),'EA-Fortescue_ReqsImport'!T:T)<1,"",_xlfn.XLOOKUP($A3,LEFT('EA-Fortescue_ReqsImport'!$A:$A,11),'EA-Fortescue_ReqsImport'!T:T))} | F3: {=IF(_xlfn.XLOOKUP($A3,LEFT('EA-Fortescue_ReqsImport'!$A:$A,11),'EA-Fortescue_ReqsImport'!U:U)<1,"",_xlfn.XLOOKUP($A3,LEFT('EA-Fortescue_ReqsImport'!$A:$A,11),'EA-Fortescue_ReqsImport'!U:U))} | G3: {=IF(_xlfn.XLOOKUP($A3,LEFT('EA-Fortescue_ReqsImport'!$A:$A,11),'EA-Fortescue_ReqsImport'!V:V)<1,"",_xlfn.XLOOKUP($A3,LEFT('EA-Fortescue_ReqsImport'!$A:$A,11),'EA-Fortescue_ReqsImport'!V:V))} | H3: {=IF(_xlfn.XLOOKUP($A3,LEFT('EA-Fortescue_ReqsImport'!$A:$A,11),'EA-Fortescue_ReqsImport'!W:W)<1,"",_xlfn.XLOOKUP($A3,LEFT('EA-Fortescue_ReqsImport'!$A:$A,11),'EA-Fortescue_ReqsImport'!W:W))} | M3: {=IF(_xlfn.XLOOKUP($A3,LEFT('EA-Fortescue_ReqsImport'!$A:$A,11),'EA-Fortescue_ReqsImport'!X:X)<1,"N/A",_xlfn.XLOOKUP($A3,LEFT('EA-Fortescue_ReqsImport'!$A:$A,11),'EA-Fortescue_ReqsImport'!X:X))} -> N/A
A4: GSP-IR-0003 | C4: {=IF(_xlfn.XLOOKUP($A4,LEFT('EA-Fortescue_ReqsImport'!$A:$A,11),'EA-Fortescue_ReqsImport'!R:R)<1,"",_xlfn.XLOOKUP($A4,LEFT('EA-Fortescue_ReqsImport'!$A:$A,11),'EA-Fortescue_ReqsImport'!R:R))} -> The interface shall provide Heavy Mining Equipment (HME) operational and load-profile input data to Delphi at a frequency of 1 Hz (one update per second), with a maximum end-to-end latency of up to 2 seconds, to support fleet simulation and energy feasibility analysis. | D4: {=IF(_xlfn.XLOOKUP($A4,LEFT('EA-Fortescue_ReqsImport'!$A:$A,11),'EA-Fortescue_ReqsImport'!S:S)<1,"",_xlfn.XLOOKUP($A4,LEFT('EA-Fortescue_ReqsImport'!$A:$A,11),'EA-Fortescue_ReqsImport'!S:S))} -> Interface Requirement | E4: {=IF(_xlfn.XLOOKUP($A4,LEFT('EA-Fortescue_ReqsImport'!$A:$A,11),'EA-Fortescue_ReqsImport'!T:T)<1,"",_xlfn.XLOOKUP($A4,LEFT('EA-Fortescue_ReqsImport'!$A:$A,11),'EA-Fortescue_ReqsImport'!T:T))} -> Green Systems Interface Register, Interface DGS-I_0023 | F4: {=IF(_xlfn.XLOOKUP($A4,LEFT('EA-Fortescue_ReqsImport'!$A:$A,11),'EA-Fortescue_ReqsImport'!U:U)<1,"",_xlfn.XLOOKUP($A4,LEFT('EA-Fortescue_ReqsImport'!$A:$A,11),'EA-Fortescue_ReqsImport'!U:U))} -> Delphi | G4: {=IF(_xlfn.XLOOKUP($A4,LEFT('EA-Fortescue_ReqsImport'!$A:$A,11),'EA-Fortescue_ReqsImport'!V:V)<1,"",_xlfn.XLOOKUP($A4,LEFT('EA-Fortescue_ReqsImport'!$A:$A,11),'EA-Fortescue_ReqsImport'!V:V))} -> Feasibility analysis requires timely data; delayed or missing data prevents simulation and energy checks. | H4: {=IF(_xlfn.XLOOKUP($A4,LEFT('EA-Fortescue_ReqsImport'!$A:$A,11),'EA-Fortescue_ReqsImport'!W:W)<1,"",_xlfn.XLOOKUP($A4,LEFT('EA-Fortescue_ReqsImport'!$A:$A,11),'EA-Fortescue_ReqsImport'!W:W))} -> 859DC-1410-001 HaulX|855DC-1541-DEL Delphi_x000D_ Project - Project Interface_x000D_ Technical-Data/Software_x000D_ This interface provides a near-term forecast of fleet energy consumption. This depends on the HaulX forecast horizon, based on a dispatch plan and mine plan. 30-40% of load based on mobile asset energy consumption. Frequency, resolution and horizon need to be determined for truck and excavator fleet on charge. State of charge, estimated time of completion._x000D_ The criticality level is LOW because, although Delphi receives fleet energy forecasts from HaulX to support planning and optimisation, the interface does not affect real-time haulage operations, safety, or production continuity. If the interface fails, Haulage and mine operations continue normally, though forecast accuracy and decision-making may be reduced. | M4: {=IF(_xlfn.XLOOKUP($A4,LEFT('EA-Fortescue_ReqsImport'!$A:$A,11),'EA-Fortescue_ReqsImport'!X:X)<1,"",_xlfn.XLOOKUP($A4,LEFT('EA-Fortescue_ReqsImport'!$A:$A,11),'EA-Fortescue_ReqsImport'!X:X))} -> Draft
A5: GSP-IR-0004 | C5: {=IF(_xlfn.XLOOKUP($A5,LEFT('EA-Fortescue_ReqsImport'!$A:$A,11),'EA-Fortescue_ReqsImport'!R:R)<1,"",_xlfn.XLOOKUP($A5,LEFT('EA-Fortescue_ReqsImport'!$A:$A,11),'EA-Fortescue_ReqsImport'!R:R))} -> The interface shall ensure completeness of all mandatory Heavy Mining Equipment (HME) load-profile data fields used by the Eclipse simulation engine. | D5: {=IF(_xlfn.XLOOKUP($A5,LEFT('EA-Fortescue_ReqsImport'!$A:$A,11),'EA-Fortescue_ReqsImport'!S:S)<1,"",_xlfn.XLOOKUP($A5,LEFT('EA-Fortescue_ReqsImport'!$A:$A,11),'EA-Fortescue_ReqsImport'!S:S))} -> Interface Requirement | E5: {=IF(_xlfn.XLOOKUP($A5,LEFT('EA-Fortescue_ReqsImport'!$A:$A,11),'EA-Fortescue_ReqsImport'!T:T)<1,"",_xlfn.XLOOKUP($A5,LEFT('EA-Fortescue_ReqsImport'!$A:$A,11),'EA-Fortescue_ReqsImport'!T:T))} -> Green Systems Interface Register, Interface DGS-I_0023 | F5: {=IF(_xlfn.XLOOKUP($A5,LEFT('EA-Fortescue_ReqsImport'!$A:$A,11),'EA-Fortescue_ReqsImport'!U:U)<1,"",_xlfn.XLOOKUP($A5,LEFT('EA-Fortescue_ReqsImport'!$A:$A,11),'EA-Fortescue_ReqsImport'!U:U))} -> Delphi | G5: {=IF(_xlfn.XLOOKUP($A5,LEFT('EA-Fortescue_ReqsImport'!$A:$A,11),'EA-Fortescue_ReqsImport'!V:V)<1,"",_xlfn.XLOOKUP($A5,LEFT('EA-Fortescue_ReqsImport'!$A:$A,11),'EA-Fortescue_ReqsImport'!V:V))} -> Missing fields lead to invalid or failed simulations. | H5: {=IF(_xlfn.XLOOKUP($A5,LEFT('EA-Fortescue_ReqsImport'!$A:$A,11),'EA-Fortescue_ReqsImport'!W:W)<1,"",_xlfn.XLOOKUP($A5,LEFT('EA-Fortescue_ReqsImport'!$A:$A,11),'EA-Fortescue_ReqsImport'!W:W))} -> 859DC-1410-001 HaulX|855DC-1541-DEL Delphi_x000D_ Project - Project Interface_x000D_ Technical-Data/Software_x000D_ This interface provides a near-term forecast of fleet energy consumption. This depends on the HaulX forecast horizon, based on a dispatch plan and mine plan. 30-40% of load based on mobile asset energy consumption. Frequency, resolution and horizon need to be determined for truck and excavator fleet on charge. State of charge, estimated time of completion._x000D_ The criticality level is LOW because, although Delphi receives fleet energy forecasts from HaulX to support planning and optimisation, the interface does not affect real-time haulage operations, safety, or production continuity. If the interface fails, Haulage and mine operations continue normally, though forecast accuracy and decision-making may be reduced. | M5: {=IF(_xlfn.XLOOKUP($A5,LEFT('EA-Fortescue_ReqsImport'!$A:$A,11),'EA-Fortescue_ReqsImport'!X:X)<1,"",_xlfn.XLOOKUP($A5,LEFT('EA-Fortescue_ReqsImport'!$A:$A,11),'EA-Fortescue_ReqsImport'!X:X))} -> Draft
A6: GSP-IR-0005 | C6: {=IF(_xlfn.XLOOKUP($A6,LEFT('EA-Fortescue_ReqsImport'!$A:$A,11),'EA-Fortescue_ReqsImport'!R:R)<1,"",_xlfn.XLOOKUP($A6,LEFT('EA-Fortescue_ReqsImport'!$A:$A,11),'EA-Fortescue_ReqsImport'!R:R))} -> The interface shall ensure integrity of transmitted values, including protection against corruption and preservation of source identifiers and timestamps. | D6: {=IF(_xlfn.XLOOKUP($A6,LEFT('EA-Fortescue_ReqsImport'!$A:$A,11),'EA-Fortescue_ReqsImport'!S:S)<1,"",_xlfn.XLOOKUP($A6,LEFT('EA-Fortescue_ReqsImport'!$A:$A,11),'EA-Fortescue_ReqsImport'!S:S))} -> Interface Requirement | E6: {=IF(_xlfn.XLOOKUP($A6,LEFT('EA-Fortescue_ReqsImport'!$A:$A,11),'EA-Fortescue_ReqsImport'!T:T)<1,"",_xlfn.XLOOKUP($A6,LEFT('EA-Fortescue_ReqsImport'!$A:$A,11),'EA-Fortescue_ReqsImport'!T:T))} -> Green Systems Interface Register, Interface DGS-I_0023 | F6: {=IF(_xlfn.XLOOKUP($A6,LEFT('EA-Fortescue_ReqsImport'!$A:$A,11),'EA-Fortescue_ReqsImport'!U:U)<1,"",_xlfn.XLOOKUP($A6,LEFT('EA-Fortescue_ReqsImport'!$A:$A,11),'EA-Fortescue_ReqsImport'!U:U))} -> Delphi | G6: {=IF(_xlfn.XLOOKUP($A6,LEFT('EA-Fortescue_ReqsImport'!$A:$A,11),'EA-Fortescue_ReqsImport'!V:V)<1,"",_xlfn.XLOOKUP($A6,LEFT('EA-Fortescue_ReqsImport'!$A:$A,11),'EA-Fortescue_ReqsImport'!V:V))} -> Compromised integrity produces incorrect feasibility results and curtailment decisions. | H6: {=IF(_xlfn.XLOOKUP($A6,LEFT('EA-Fortescue_ReqsImport'!$A:$A,11),'EA-Fortescue_ReqsImport'!W:W)<1,"",_xlfn.XLOOKUP($A6,LEFT('EA-Fortescue_ReqsImport'!$A:$A,11),'EA-Fortescue_ReqsImport'!W:W))} -> 859DC-1410-001 HaulX|855DC-1541-DEL Delphi_x000D_ Project - Project Interface_x000D_ Technical-Data/Software_x000D_ This interface provides a near-term forecast of fleet energy consumption. This depends on the HaulX forecast horizon, based on a dispatch plan and mine plan. 30-40% of load based on mobile asset energy consumption. Frequency, resolution and horizon need to be determined for truck and excavator fleet on charge. State of charge, estimated time of completion._x000D_ The criticality level is LOW because, although Delphi receives fleet energy forecasts from HaulX to support planning and optimisation, the interface does not affect real-time haulage operations, safety, or production continuity. If the interface fails, Haulage and mine operations continue normally, though forecast accuracy and decision-making may be reduced. | M6: {=IF(_xlfn.XLOOKUP($A6,LEFT('EA-Fortescue_ReqsImport'!$A:$A,11),'EA-Fortescue_ReqsImport'!X:X)<1,"",_xlfn.XLOOKUP($A6,LEFT('EA-Fortescue_ReqsImport'!$A:$A,11),'EA-Fortescue_ReqsImport'!X:X))} -> Draft
A7: GSP-IR-0006 | C7: {=IF(_xlfn.XLOOKUP($A7,LEFT('EA-Fortescue_ReqsImport'!$A:$A,11),'EA-Fortescue_ReqsImport'!R:R)<1,"",_xlfn.XLOOKUP($A7,LEFT('EA-Fortescue_ReqsImport'!$A:$A,11),'EA-Fortescue_ReqsImport'!R:R))} -> The interface shall provide deterministic error handling and clear notifications when Heavy Mining Equipment (HME) data is missing, delayed, or invalid. | D7: {=IF(_xlfn.XLOOKUP($A7,LEFT('EA-Fortescue_ReqsImport'!$A:$A,11),'EA-Fortescue_ReqsImport'!S:S)<1,"",_xlfn.XLOOKUP($A7,LEFT('EA-Fortescue_ReqsImport'!$A:$A,11),'EA-Fortescue_ReqsImport'!S:S))} -> Interface Requirement | E7: {=IF(_xlfn.XLOOKUP($A7,LEFT('EA-Fortescue_ReqsImport'!$A:$A,11),'EA-Fortescue_ReqsImport'!T:T)<1,"",_xlfn.XLOOKUP($A7,LEFT('EA-Fortescue_ReqsImport'!$A:$A,11),'EA-Fortescue_ReqsImport'!T:T))} -> Green Systems Interface Register, Interface DGS-I_0023 | F7: {=IF(_xlfn.XLOOKUP($A7,LEFT('EA-Fortescue_ReqsImport'!$A:$A,11),'EA-Fortescue_ReqsImport'!U:U)<1,"",_xlfn.XLOOKUP($A7,LEFT('EA-Fortescue_ReqsImport'!$A:$A,11),'EA-Fortescue_ReqsImport'!U:U))} -> Delphi | G7: {=IF(_xlfn.XLOOKUP($A7,LEFT('EA-Fortescue_ReqsImport'!$A:$A,11),'EA-Fortescue_ReqsImport'!V:V)<1,"",_xlfn.XLOOKUP($A7,LEFT('EA-Fortescue_ReqsImport'!$A:$A,11),'EA-Fortescue_ReqsImport'!V:V))} -> Clear fault visibility is required to avoid silent degradation of planning capability. | H7: {=IF(_xlfn.XLOOKUP($A7,LEFT('EA-Fortescue_ReqsImport'!$A:$A,11),'EA-Fortescue_ReqsImport'!W:W)<1,"",_xlfn.XLOOKUP($A7,LEFT('EA-Fortescue_ReqsImport'!$A:$A,11),'EA-Fortescue_ReqsImport'!W:W))} -> 859DC-1410-001 HaulX|855DC-1541-DEL Delphi_x000D_ Project - Project Interface_x000D_ Technical-Data/Software_x000D_ This interface provides a near-term forecast of fleet energy consumption. This depends on the HaulX forecast horizon, based on a dispatch plan and mine plan. 30-40% of load based on mobile asset energy consumption. Frequency, resolution and horizon need to be determined for truck and excavator fleet on charge. State of charge, estimated time of completion._x000D_ The criticality level is LOW because, although Delphi receives fleet energy forecasts from HaulX to support planning and optimisation, the interface does not affect real-time haulage operations, safety, or production continuity. If the interface fails, Haulage and mine operations continue normally, though forecast accuracy and decision-making may be reduced. | M7: {=IF(_xlfn.XLOOKUP($A7,LEFT('EA-Fortescue_ReqsImport'!$A:$A,11),'EA-Fortescue_ReqsImport'!X:X)<1,"",_xlfn.XLOOKUP($A7,LEFT('EA-Fortescue_ReqsImport'!$A:$A,11),'EA-Fortescue_ReqsImport'!X:X))} -> Draft
A8: GSP-IR-0007 | C8: {=IF(_xlfn.XLOOKUP($A8,LEFT('EA-Fortescue_ReqsImport'!$A:$A,11),'EA-Fortescue_ReqsImport'!R:R)<1,"",_xlfn.XLOOKUP($A8,LEFT('EA-Fortescue_ReqsImport'!$A:$A,11),'EA-Fortescue_ReqsImport'!R:R))} -> The interface shall provide Delphi with continuous access to Snowflake datasets containing historical and actual operational data required for short-term planning. | D8: {=IF(_xlfn.XLOOKUP($A8,LEFT('EA-Fortescue_ReqsImport'!$A:$A,11),'EA-Fortescue_ReqsImport'!S:S)<1,"",_xlfn.XLOOKUP($A8,LEFT('EA-Fortescue_ReqsImport'!$A:$A,11),'EA-Fortescue_ReqsImport'!S:S))} -> Interface Requirement | E8: {=IF(_xlfn.XLOOKUP($A8,LEFT('EA-Fortescue_ReqsImport'!$A:$A,11),'EA-Fortescue_ReqsImport'!T:T)<1,"",_xlfn.XLOOKUP($A8,LEFT('EA-Fortescue_ReqsImport'!$A:$A,11),'EA-Fortescue_ReqsImport'!T:T))} -> Green Systems Interface Register, Interface DGS-I_0345 | F8: {=IF(_xlfn.XLOOKUP($A8,LEFT('EA-Fortescue_ReqsImport'!$A:$A,11),'EA-Fortescue_ReqsImport'!U:U)<1,"",_xlfn.XLOOKUP($A8,LEFT('EA-Fortescue_ReqsImport'!$A:$A,11),'EA-Fortescue_ReqsImport'!U:U))} -> Delphi | G8: {=IF(_xlfn.XLOOKUP($A8,LEFT('EA-Fortescue_ReqsImport'!$A:$A,11),'EA-Fortescue_ReqsImport'!V:V)<1,"",_xlfn.XLOOKUP($A8,LEFT('EA-Fortescue_ReqsImport'!$A:$A,11),'EA-Fortescue_ReqsImport'!V:V))} -> Continuous access to historical and actual data is required to support accurate short-term planning; interruptions or gaps degrade forecast quality and decision-making. | H8: {=IF(_xlfn.XLOOKUP($A8,LEFT('EA-Fortescue_ReqsImport'!$A:$A,11),'EA-Fortescue_ReqsImport'!W:W)<1,"",_xlfn.XLOOKUP($A8,LEFT('EA-Fortescue_ReqsImport'!$A:$A,11),'EA-Fortescue_ReqsImport'!W:W))} -> 005OP-0000-006 Snowflake (General)|855DC-1541-DEL Delphi_x000D_ Project - Project Interface_x000D_ Technical-Data/Software_x000D_ This interface collects general actuals and historical data residing in Snowflake. Snowflake provides a 'time travel' function, which is from 1 day (default) up to a maximum of 90 days._x000D_ This interface is rated HIGH because accurate historical and actual data underpins short-term forecasting, model validation, and operational planning accuracy. Loss or corruption of this data materially degrades forecast reliability, increasing the risk of incorrect generation dispatch, inefficient curtailment decisions, and potential instability in power management. Reliable historical data is essential for maintaining confidence in optimisation and planning outputs. | M8: {=IF(_xlfn.XLOOKUP($A8,LEFT('EA-Fortescue_ReqsImport'!$A:$A,11),'EA-Fortescue_ReqsImport'!X:X)<1,"",_xlfn.XLOOKUP($A8,LEFT('EA-Fortescue_ReqsImport'!$A:$A,11),'EA-Fortescue_ReqsImport'!X:X))} -> Draft
A9: GSP-IR-0008 | C9: {=IF(_xlfn.XLOOKUP($A9,LEFT('EA-Fortescue_ReqsImport'!$A:$A,11),'EA-Fortescue_ReqsImport'!R:R)<1,"",_xlfn.XLOOKUP($A9,LEFT('EA-Fortescue_ReqsImport'!$A:$A,11),'EA-Fortescue_ReqsImport'!R:R))} -> The interface shall maintain a minimum availability of 99.9% each calendar month, allowing no more than 43.2 minutes of unplanned downtime per month, to ensure planning and forecasting accuracy is not materially degraded | D9: {=IF(_xlfn.XLOOKUP($A9,LEFT('EA-Fortescue_ReqsImport'!$A:$A,11),'EA-Fortescue_ReqsImport'!S:S)<1,"",_xlfn.XLOOKUP($A9,LEFT('EA-Fortescue_ReqsImport'!$A:$A,11),'EA-Fortescue_ReqsImport'!S:S))} -> Interface Requirement | E9: {=IF(_xlfn.XLOOKUP($A9,LEFT('EA-Fortescue_ReqsImport'!$A:$A,11),'EA-Fortescue_ReqsImport'!T:T)<1,"",_xlfn.XLOOKUP($A9,LEFT('EA-Fortescue_ReqsImport'!$A:$A,11),'EA-Fortescue_ReqsImport'!T:T))} -> Green Systems Interface Register, Interface DGS-I_0345 | F9: {=IF(_xlfn.XLOOKUP($A9,LEFT('EA-Fortescue_ReqsImport'!$A:$A,11),'EA-Fortescue_ReqsImport'!U:U)<1,"",_xlfn.XLOOKUP($A9,LEFT('EA-Fortescue_ReqsImport'!$A:$A,11),'EA-Fortescue_ReqsImport'!U:U))} -> Delphi | G9: {=IF(_xlfn.XLOOKUP($A9,LEFT('EA-Fortescue_ReqsImport'!$A:$A,11),'EA-Fortescue_ReqsImport'!V:V)<1,"",_xlfn.XLOOKUP($A9,LEFT('EA-Fortescue_ReqsImport'!$A:$A,11),'EA-Fortescue_ReqsImport'!V:V))} -> Unplanned outages increase the risk of unplanned load curtailment and unsafe conditions. | H9: {=IF(_xlfn.XLOOKUP($A9,LEFT('EA-Fortescue_ReqsImport'!$A:$A,11),'EA-Fortescue_ReqsImport'!W:W)<1,"",_xlfn.XLOOKUP($A9,LEFT('EA-Fortescue_ReqsImport'!$A:$A,11),'EA-Fortescue_ReqsImport'!W:W))} -> 005OP-0000-006 Snowflake (General)|855DC-1541-DEL Delphi_x000D_ Project - Project Interface_x000D_ Technical-Data/Software_x000D_ This interface collects general actuals and historical data residing in Snowflake. Snowflake provides a 'time travel' function, which is from 1 day (default) up to a maximum of 90 days._x000D_ This interface is rated HIGH because accurate historical and actual data underpins short-term forecasting, model validation, and operational planning accuracy. Loss or corruption of this data materially degrades forecast reliability, increasing the risk of incorrect generation dispatch, inefficient curtailment decisions, and potential instability in power management. Reliable historical data is essential for maintaining confidence in optimisation and planning outputs. | M9: {=IF(_xlfn.XLOOKUP($A9,LEFT('EA-Fortescue_ReqsImport'!$A:$A,11),'EA-Fortescue_ReqsImport'!X:X)<1,"",_xlfn.XLOOKUP($A9,LEFT('EA-Fortescue_ReqsImport'!$A:$A,11),'EA-Fortescue_ReqsImport'!X:X))} -> Draft
A10: GSP-IR-0009 | C10: {=IF(_xlfn.XLOOKUP($A10,LEFT('EA-Fortescue_ReqsImport'!$A:$A,11),'EA-Fortescue_ReqsImport'!R:R)<1,"",_xlfn.XLOOKUP($A10,LEFT('EA-Fortescue_ReqsImport'!$A:$A,11),'EA-Fortescue_ReqsImport'!R:R))} -> The interface shall provide version-controlled historical datasets to support consistent retrospective analysis and model training. | D10: {=IF(_xlfn.XLOOKUP($A10,LEFT('EA-Fortescue_ReqsImport'!$A:$A,11),'EA-Fortescue_ReqsImport'!S:S)<1,"",_xlfn.XLOOKUP($A10,LEFT('EA-Fortescue_ReqsImport'!$A:$A,11),'EA-Fortescue_ReqsImport'!S:S))} -> Interface Requirement | E10: {=IF(_xlfn.XLOOKUP($A10,LEFT('EA-Fortescue_ReqsImport'!$A:$A,11),'EA-Fortescue_ReqsImport'!T:T)<1,"",_xlfn.XLOOKUP($A10,LEFT('EA-Fortescue_ReqsImport'!$A:$A,11),'EA-Fortescue_ReqsImport'!T:T))} -> Green Systems Interface Register, Interface DGS-I_0345 | F10: {=IF(_xlfn.XLOOKUP($A10,LEFT('EA-Fortescue_ReqsImport'!$A:$A,11),'EA-Fortescue_ReqsImport'!U:U)<1,"",_xlfn.XLOOKUP($A10,LEFT('EA-Fortescue_ReqsImport'!$A:$A,11),'EA-Fortescue_ReqsImport'!U:U))} -> Delphi | G10: {=IF(_xlfn.XLOOKUP($A10,LEFT('EA-Fortescue_ReqsImport'!$A:$A,11),'EA-Fortescue_ReqsImport'!V:V)<1,"",_xlfn.XLOOKUP($A10,LEFT('EA-Fortescue_ReqsImport'!$A:$A,11),'EA-Fortescue_ReqsImport'!V:V))} -> Consistent datasets are needed to reproduce and improve forecasting models. | H10: {=IF(_xlfn.XLOOKUP($A10,LEFT('EA-Fortescue_ReqsImport'!$A:$A,11),'EA-Fortescue_ReqsImport'!W:W)<1,"",_xlfn.XLOOKUP($A10,LEFT('EA-Fortescue_ReqsImport'!$A:$A,11),'EA-Fortescue_ReqsImport'!W:W))} -> 005OP-0000-006 Snowflake (General)|855DC-1541-DEL Delphi_x000D_ Project - Project Interface_x000D_ Technical-Data/Software_x000D_ This interface collects general actuals and historical data residing in Snowflake. Snowflake provides a 'time travel' function, which is from 1 day (default) up to a maximum of 90 days._x000D_ This interface is rated HIGH because accurate historical and actual data underpins short-term forecasting, model validation, and operational planning accuracy. Loss or corruption of this data materially degrades forecast reliability, increasing the risk of incorrect generation dispatch, inefficient curtailment decisions, and potential instability in power management. Reliable historical data is essential for maintaining confidence in optimisation and planning outputs. | M10: {=IF(_xlfn.XLOOKUP($A10,LEFT('EA-Fortescue_ReqsImport'!$A:$A,11),'EA-Fortescue_ReqsImport'!X:X)<1,"",_xlfn.XLOOKUP($A10,LEFT('EA-Fortescue_ReqsImport'!$A:$A,11),'EA-Fortescue_ReqsImport'!X:X))} -> Draft
A11: GSP-IR-0010 | C11: {=IF(_xlfn.XLOOKUP($A11,LEFT('EA-Fortescue_ReqsImport'!$A:$A,11),'EA-Fortescue_ReqsImport'!R:R)<1,"",_xlfn.XLOOKUP($A11,LEFT('EA-Fortescue_ReqsImport'!$A:$A,11),'EA-Fortescue_ReqsImport'!R:R))} -> The interface shall apply data-quality checks, including type, range, and completeness validation, before data is ingested into Delphi. | D11: {=IF(_xlfn.XLOOKUP($A11,LEFT('EA-Fortescue_ReqsImport'!$A:$A,11),'EA-Fortescue_ReqsImport'!S:S)<1,"",_xlfn.XLOOKUP($A11,LEFT('EA-Fortescue_ReqsImport'!$A:$A,11),'EA-Fortescue_ReqsImport'!S:S))} -> Interface Requirement | E11: {=IF(_xlfn.XLOOKUP($A11,LEFT('EA-Fortescue_ReqsImport'!$A:$A,11),'EA-Fortescue_ReqsImport'!T:T)<1,"",_xlfn.XLOOKUP($A11,LEFT('EA-Fortescue_ReqsImport'!$A:$A,11),'EA-Fortescue_ReqsImport'!T:T))} -> Green Systems Interface Register, Interface DGS-I_0345 | F11: {=IF(_xlfn.XLOOKUP($A11,LEFT('EA-Fortescue_ReqsImport'!$A:$A,11),'EA-Fortescue_ReqsImport'!U:U)<1,"",_xlfn.XLOOKUP($A11,LEFT('EA-Fortescue_ReqsImport'!$A:$A,11),'EA-Fortescue_ReqsImport'!U:U))} -> Delphi | G11: {=IF(_xlfn.XLOOKUP($A11,LEFT('EA-Fortescue_ReqsImport'!$A:$A,11),'EA-Fortescue_ReqsImport'!V:V)<1,"",_xlfn.XLOOKUP($A11,LEFT('EA-Fortescue_ReqsImport'!$A:$A,11),'EA-Fortescue_ReqsImport'!V:V))} -> Low-quality data can drive unsafe or inefficient planning outcomes. | H11: {=IF(_xlfn.XLOOKUP($A11,LEFT('EA-Fortescue_ReqsImport'!$A:$A,11),'EA-Fortescue_ReqsImport'!W:W)<1,"",_xlfn.XLOOKUP($A11,LEFT('EA-Fortescue_ReqsImport'!$A:$A,11),'EA-Fortescue_ReqsImport'!W:W))} -> 005OP-0000-006 Snowflake (General)|855DC-1541-DEL Delphi_x000D_ Project - Project Interface_x000D_ Technical-Data/Software_x000D_ This interface collects general actuals and historical data residing in Snowflake. Snowflake provides a 'time travel' function, which is from 1 day (default) up to a maximum of 90 days._x000D_ This interface is rated HIGH because accurate historical and actual data underpins short-term forecasting, model validation, and operational planning accuracy. Loss or corruption of this data materially degrades forecast reliability, increasing the risk of incorrect generation dispatch, inefficient curtailment decisions, and potential instability in power management. Reliable historical data is essential for maintaining confidence in optimisation and planning outputs. | M11: {=IF(_xlfn.XLOOKUP($A11,LEFT('EA-Fortescue_ReqsImport'!$A:$A,11),'EA-Fortescue_ReqsImport'!X:X)<1,"",_xlfn.XLOOKUP($A11,LEFT('EA-Fortescue_ReqsImport'!$A:$A,11),'EA-Fortescue_ReqsImport'!X:X))} -> Draft
A12: GSP-IR-0011 | C12: {=IF(_xlfn.XLOOKUP($A12,LEFT('EA-Fortescue_ReqsImport'!$A:$A,11),'EA-Fortescue_ReqsImport'!R:R)<1,"",_xlfn.XLOOKUP($A12,LEFT('EA-Fortescue_ReqsImport'!$A:$A,11),'EA-Fortescue_ReqsImport'!R:R))} -> The interface shall supply real-time operational electrical load data from Ignition SCADA to Delphi for plan-versus-actual calculations. | D12: {=IF(_xlfn.XLOOKUP($A12,LEFT('EA-Fortescue_ReqsImport'!$A:$A,11),'EA-Fortescue_ReqsImport'!S:S)<1,"",_xlfn.XLOOKUP($A12,LEFT('EA-Fortescue_ReqsImport'!$A:$A,11),'EA-Fortescue_ReqsImport'!S:S))} -> Interface Requirement | E12: {=IF(_xlfn.XLOOKUP($A12,LEFT('EA-Fortescue_ReqsImport'!$A:$A,11),'EA-Fortescue_ReqsImport'!T:T)<1,"",_xlfn.XLOOKUP($A12,LEFT('EA-Fortescue_ReqsImport'!$A:$A,11),'EA-Fortescue_ReqsImport'!T:T))} -> Green Systems Interface Register, Interface DGS-I_0344 | F12: {=IF(_xlfn.XLOOKUP($A12,LEFT('EA-Fortescue_ReqsImport'!$A:$A,11),'EA-Fortescue_ReqsImport'!U:U)<1,"",_xlfn.XLOOKUP($A12,LEFT('EA-Fortescue_ReqsImport'!$A:$A,11),'EA-Fortescue_ReqsImport'!U:U))} -> Delphi | G12: {=IF(_xlfn.XLOOKUP($A12,LEFT('EA-Fortescue_ReqsImport'!$A:$A,11),'EA-Fortescue_ReqsImport'!V:V)<1,"",_xlfn.XLOOKUP($A12,LEFT('EA-Fortescue_ReqsImport'!$A:$A,11),'EA-Fortescue_ReqsImport'!V:V))} -> Plan-versus-actual comparison requires current load measurements. | H12: {=IF(_xlfn.XLOOKUP($A12,LEFT('EA-Fortescue_ReqsImport'!$A:$A,11),'EA-Fortescue_ReqsImport'!W:W)<1,"",_xlfn.XLOOKUP($A12,LEFT('EA-Fortescue_ReqsImport'!$A:$A,11),'EA-Fortescue_ReqsImport'!W:W))} -> 005OP-0000-017 Ignition|855DC-1541-DEL Delphi_x000D_ Project - Project Interface_x000D_ Technical-Data/Software_x000D_ This interface supplies operational data for ground-truth load for plan/forecast vs. actual load calculations._x000D_ This interface is rated HIGH because it provides the authoritative operational load data required to maintain an accurate view of total system demand. Loss, delay, or corruption of this data undermines the integrity of load calculations and forecasting models, increasing the risk of overload conditions, incorrect dispatch or curtailment decisions, and potential safety incidents. Reliable ground-truth data is essential for maintaining power system stability and operational assurance. | M12: {=IF(_xlfn.XLOOKUP($A12,LEFT('EA-Fortescue_ReqsImport'!$A:$A,11),'EA-Fortescue_ReqsImport'!X:X)<1,"",_xlfn.XLOOKUP($A12,LEFT('EA-Fortescue_ReqsImport'!$A:$A,11),'EA-Fortescue_ReqsImport'!X:X))} -> Draft
A13: GSP-IR-0012 | C13: {=IF(_xlfn.XLOOKUP($A13,LEFT('EA-Fortescue_ReqsImport'!$A:$A,11),'EA-Fortescue_ReqsImport'!R:R)<1,"",_xlfn.XLOOKUP($A13,LEFT('EA-Fortescue_ReqsImport'!$A:$A,11),'EA-Fortescue_ReqsImport'!R:R))} -> The interface shall ensure that SCADA load-data latency does not exceed 2 seconds end-to-end, measured from data capture to availability in the consuming system, to meet the operational threshold required for safe real-time decision-making. | D13: {=IF(_xlfn.XLOOKUP($A13,LEFT('EA-Fortescue_ReqsImport'!$A:$A,11),'EA-Fortescue_ReqsImport'!S:S)<1,"",_xlfn.XLOOKUP($A13,LEFT('EA-Fortescue_ReqsImport'!$A:$A,11),'EA-Fortescue_ReqsImport'!S:S))} -> Interface Requirement | E13: {=IF(_xlfn.XLOOKUP($A13,LEFT('EA-Fortescue_ReqsImport'!$A:$A,11),'EA-Fortescue_ReqsImport'!T:T)<1,"",_xlfn.XLOOKUP($A13,LEFT('EA-Fortescue_ReqsImport'!$A:$A,11),'EA-Fortescue_ReqsImport'!T:T))} -> Green Systems Interface Register, Interface DGS-I_0344 | F13: {=IF(_xlfn.XLOOKUP($A13,LEFT('EA-Fortescue_ReqsImport'!$A:$A,11),'EA-Fortescue_ReqsImport'!U:U)<1,"",_xlfn.XLOOKUP($A13,LEFT('EA-Fortescue_ReqsImport'!$A:$A,11),'EA-Fortescue_ReqsImport'!U:U))} -> Delphi | G13: {=IF(_xlfn.XLOOKUP($A13,LEFT('EA-Fortescue_ReqsImport'!$A:$A,11),'EA-Fortescue_ReqsImport'!V:V)<1,"",_xlfn.XLOOKUP($A13,LEFT('EA-Fortescue_ReqsImport'!$A:$A,11),'EA-Fortescue_ReqsImport'!V:V))} -> Excessive latency undermines safe curtailment and control decisions. | H13: {=IF(_xlfn.XLOOKUP($A13,LEFT('EA-Fortescue_ReqsImport'!$A:$A,11),'EA-Fortescue_ReqsImport'!W:W)<1,"",_xlfn.XLOOKUP($A13,LEFT('EA-Fortescue_ReqsImport'!$A:$A,11),'EA-Fortescue_ReqsImport'!W:W))} -> 005OP-0000-017 Ignition|855DC-1541-DEL Delphi_x000D_ Project - Project Interface_x000D_ Technical-Data/Software_x000D_ This interface supplies operational data for ground-truth load for plan/forecast vs. actual load calculations._x000D_ This interface is rated HIGH because it provides the authoritative operational load data required to maintain an accurate view of total system demand. Loss, delay, or corruption of this data undermines the integrity of load calculations and forecasting models, increasing the risk of overload conditions, incorrect dispatch or curtailment decisions, and potential safety incidents. Reliable ground-truth data is essential for maintaining power system stability and operational assurance. | M13: {=IF(_xlfn.XLOOKUP($A13,LEFT('EA-Fortescue_ReqsImport'!$A:$A,11),'EA-Fortescue_ReqsImport'!X:X)<1,"",_xlfn.XLOOKUP($A13,LEFT('EA-Fortescue_ReqsImport'!$A:$A,11),'EA-Fortescue_ReqsImport'!X:X))} -> Draft
